<?xml version="1.0"?>

<robot name="myrobot" xmlns:xacro="http://www.ros.org/wiki/xacro">

<!--<xacro:include filename="$(find spcbot_description)/urdf/plat4m.gazebo"/>-->


<!-- A RENOMMER EN base_link-->
<link name="link0_p4m">
  <inertial>
    <origin xyz="0.0 0.0 0.0" rpy="0.0 0.0 0.0"/>
    <mass value="0.0"/>
    <inertia ixx="0" ixy="0.0" ixz="0.0" iyy="0.0" iyz="0.0" izz="0.0"/>
  </inertial>
  <visual name="">
    <origin xyz="-0.727 -1.032 0.01935" rpy="-1.5708 0.0 0.0"/>
    <geometry>
      <mesh filename="package://plat4m_description/meshes/link0_at_p4m.STL" scale="0.001 0.001 0.001"/>
    </geometry>
    <material name="">
      <color rgba="1 1 1 1"/>
      <texture filename=""/>
    </material>
  </visual>
  <collision>
    <origin xyz="0.0 0.0 0.0" rpy="0.0 0.0 0.0"/>
    <geometry>
      <mesh filename="package://plat4m_description/meshes/link0_at_p4m.STL" scale="0.01 0.01 0.01"/>
    </geometry>
  </collision>
</link>

<joint name="joint_0_1_l2" type="fixed">
  <origin xyz="0.50 0.0 0.01935" rpy="0.0 0.0 0.0"/>
  <parent link="link0_p4m"/>
  <child link="link1_atache_l2"/>
</joint>


<link name="link1_atache_l2">
  <inertial>
    <origin xyz="0.0 0.0 0.0" rpy="0.0 0.0 0.0"/>
    <mass value="0.0"/>
    <inertia ixx="0.0" ixy="0.0" ixz="0.0" iyy="0.0" iyz="0.0" izz="0.0"/>
  </inertial>
  <visual name="">
    <origin xyz="0.0 0.0 0.0" rpy="0.0 0.0 0.0"/>
    <geometry>
      <mesh filename="package://plat4m_description/meshes/link1_atache.stl" scale="0.01 0.01 0.01"/>
    </geometry>
    <material name="">
      <color rgba="1.0 0.0 0.0 1.0"/>
      <texture filename=""/>
    </material>
  </visual>
  <collision>
    <origin xyz="0.0 0.0 0.0" rpy="0.0 0.0 0.0"/>
    <geometry>
      <mesh filename="package://plat4m_description/meshes/link1_atache.stl" scale="0.01 0.01 0.01"/>
    </geometry>
  </collision>
</link>

<joint name="joint_1_2_l2" type="continuous">
  <origin xyz="0.000 0.000 0.021" rpy="0.0 0.0 0.0"/>
  <parent link="link1_atache_l2"/>
  <child link="link2_act_l2"/>
  <axis xyz="0.0 1.0 0.0"/>
</joint>

<!-- A AJOUTER POUR LA SIMU - DEBUT-->
<gazebo>
    <plugin name="gazebo_ros_control" filename="libgazebo_ros_control.so">
    <robotNamespace>/</robotNamespace>
    <legacyModeNS>true</legacyModeNS>
    </plugin>
</gazebo>
<!-- A AJOUTER POUR LA SIMU - FIN-->


<!-- A AJOUTER POUR CHACUNE DE TES ROUES et de TES PISTONS
JE TE CONSEILLE DE REVOIR TON CODE
POUR PROFITER DES MACROS XACRO-->
<!-- DEBUT DE l'AJOUT -->
<transmission name="XXX_wheel_trans">
    <type>transmission_interface/SimpleTransmission</type>
    <actuator name="XXX_wheel_motor">
        <mechanicalReduction>1</mechanicalReduction>
    </actuator>
    <joint name="XXX_wheel_joint">
        <hardwareInterface>hardware_interface/VelocityJointInterface</hardwareInterface>
    </joint>
</transmission>

<gazebo reference="XXX_wheel">
    <mu1 value="2.0"/>
    <mu2 value="1.0"/>
    <kp value="10000000.0" />
    <kd value="1.0" />
    <material>Gazebo/Black</material>
</gazebo>
<!-- FIN DE l'AJOUT -->



<link name="link2_act_l2">
  <inertial>
    <origin xyz="0.0 0.0 0.0" rpy="0.0 0.0 0.0"/>
    <mass value="0.0"/>
    <inertia ixx="0.0" ixy="0.0" ixz="0.0" iyy="0.0" iyz="0.0" izz="0.0"/>
  </inertial>
  <visual name="">
    <origin xyz="0.0 0.0 0.0" rpy="0.0 0.0 0.0"/>
    <geometry>
      <mesh filename="package://plat4m_description/meshes/link2_act.stl" scale="0.01 0.01 0.01"/>   
       </geometry>
    <material name="">
      <color rgba="1.0 0.0 0.0 1.0"/>
      <texture filename=""/>
    </material>
  </visual>
  <collision>
    <origin xyz="0.0 0.0 0.0" rpy="0.0 0.0 0.0"/>
    <geometry>
      <mesh filename="package://plat4m_description/meshes/link2_act.stl" scale="0.01 0.01 0.01"/>   
    </geometry>
  </collision>
</link>

<joint name="joint_2_3_l2" type="prismatic">
  <origin xyz="0.03 0.0 0.0" rpy="0.0 0.0 0.0"/>
  <parent link="link2_act_l2"/>
  <child link="link3_tige_l2"/>
  <axis xyz="1.0 0.0 0.0"/>
  <limit lower="0.000" upper="0.070" effort="100.0" velocity="20.0"/>
</joint>

<link name="link3_tige_l2">
  <inertial>
    <origin xyz="0.0 0.0 0.0" rpy="0.0 0.0 0.0"/>
    <mass value="0.0"/>
    <inertia ixx="0.0" ixy="0.0" ixz="0.0" iyy="0.0" iyz="0.0" izz="0.0"/>
  </inertial>
  <visual name="">
    <origin xyz="0.0 0.0 0.0" rpy="0.0 0.0 0.0"/>
      <geometry>
      <mesh filename="package://plat4m_description/meshes/link3_tige.stl" scale="0.01 0.01 0.01"/>   
    </geometry>
    <material name="">
      <color rgba="1.0 0.0 0.0 1.0"/>
      <texture filename=""/>
    </material>
  </visual>
  <collision>
    <origin xyz="0.0 0.0 0.0" rpy="0.0 0.0 0.0"/>
    <geometry>
      <mesh filename="package://plat4m_description/meshes/link3_tige.stl" scale="0.01 0.01 0.01"/>   
    </geometry>
  </collision>
</link>


<link name="link4_bras_l2">
  <inertial>
    <origin xyz="0.0 0.0 0.0" rpy="0.0 0.0 0.0"/>
    <mass value="0.0"/>
    <inertia ixx="0.0" ixy="0.0" ixz="0.0" iyy="0.0" iyz="0.0" izz="0.0"/>
  </inertial>
  <visual name="">
    <origin xyz="0.0 0.0 0.0" rpy="0.0 0.0 0.0"/>
      <geometry>
      <mesh filename="package://plat4m_description/meshes/link4_bras.stl" scale="0.01 0.01 0.01"/>   
    </geometry>
    <material name="">
      <color rgba="1.0 0.0 0.0 1.0"/>
      <texture filename=""/>
    </material>
  </visual>
  <collision>
    <origin xyz="0.0 0.0 0.0" rpy="0.0 0.0 0.0"/>
    <geometry>
      <mesh filename="package://plat4m_description/meshes/link4_bras.stl" scale="0.01 0.01 0.01"/>   
    </geometry>
  </collision>
</link>

<joint name="joint_0_5_l2" type="fixed">
  <origin xyz="0.65 0.0 0.01935" rpy="0.0 0.0 0.0"/>
  <parent link="link0_p4m"/>
  <child link="link5_atpiv_l2"/>
</joint>

<joint name="joint_4_5_l2" type="revolute">
  <origin xyz="0.0 0.0 0.0161" rpy="0.0 0.0 0.0"/>
  <parent link="link5_atpiv_l2"/>
  <child link="link4_bras_l2"/>
  <axis xyz="0.0 -1.0 0.0"/>
  <limit lower="0.000" upper="1" effort="100.0" velocity="20.0"/>
</joint>

<link name="link5_atpiv_l2">
  <inertial>
    <origin xyz="0.0 0.0 0.0" rpy="0.0 0.0 0.0"/>
    <mass value="0.0"/>
    <inertia ixx="0.0" ixy="0.0" ixz="0.0" iyy="0.0" iyz="0.0" izz="0.0"/>
  </inertial>
  <visual name="">
    <origin xyz="0.0 0.0 0.0" rpy="0.0 0.0 0.0"/>
      <geometry>
      <mesh filename="package://plat4m_description/meshes/link5_atpiv.stl" scale="0.01 0.01 0.01"/>   
    </geometry>
    <material name="">
      <color rgba="1.0 0.0 0.0 1.0"/>
      <texture filename=""/>
    </material>
  </visual>
  <collision>
    <origin xyz="0.0 0.0 0.0" rpy="0.0 0.0 0.0"/>
    <geometry>
      <mesh filename="package://plat4m_description/meshes/link5_atpiv.stl" scale="0.01 0.01 0.01"/>   
    </geometry>
  </collision>
</link>

<joint name="joint_5_6_l2" type="continuous">
  <origin xyz="0.120 0.000 -0.033" rpy="0.0 -0.27 0.0"/>
  <parent link="link4_bras_l2"/>
  <child link="link6_roubi_l2"/>
  <axis xyz="1.0 0.0 0.0"/>
</joint>

<link name="link6_roubi_l2">
  <inertial>
    <origin xyz="0.0 0.0 0.0" rpy="0.0 0.0 0.0"/>
    <mass value="0.0"/>
    <inertia ixx="0.0" ixy="0.0" ixz="0.0" iyy="0.0" iyz="0.0" izz="0.0"/>
  </inertial>
  <visual name="">
    <origin xyz="0.0 0.0 0.0" rpy="0.0 0.0 0.0"/>
      <geometry>
      <mesh filename="package://plat4m_description/meshes/link6_roubi.stl" scale="0.01 0.01 0.01"/>   
    </geometry>
    <material name="">
      <color rgba="1.0 0.0 0.0 1.0"/>
      <texture filename=""/>
    </material>
  </visual>
  <collision>
    <origin xyz="0.0 0.0 0.0" rpy="0.0 0.0 0.0"/>
    <geometry>
      <mesh filename="package://plat4m_description/meshes/link6_roubi.stl" scale="0.01 0.01 0.01"/>   
    </geometry>
  </collision>
</link>

<joint name="joint_0_7_l2" type="prismatic">
  <origin xyz="0.7 0.1 0.01935" rpy="0.0 0.0 0.0"/>
  <parent link="link0_p4m"/>
  <child link="link7_brasimp_l2"/>
  <axis xyz="-1.0 0.0 0.0"/>
  <limit lower="0.0" upper="0.1" effort="20.0" velocity="20.0"/>
</joint>

<link name="link7_brasimp_l2">
  <inertial>
    <origin xyz="0.0 0.0 0.0" rpy="0.0 0.0 0.0"/>
    <mass value="0.0"/>
    <inertia ixx="0.0" ixy="0.0" ixz="0.0" iyy="0.0" iyz="0.0" izz="0.0"/>
  </inertial>
  <visual name="">
    <origin xyz="0.0 0.0 0.0" rpy="0.0 0.0 0.0"/>
      <geometry>
      <mesh filename="package://plat4m_description/meshes/link7_brasimp.stl" scale="0.01 0.01 0.01"/>   
    </geometry>
    <material name="">
      <color rgba="1.0 0.0 0.0 1.0"/>
      <texture filename=""/>
    </material>
  </visual>
  <collision>
    <origin xyz="0.0 0.0 0.0" rpy="0.0 0.0 0.0"/>
    <geometry>
      <mesh filename="package://plat4m_description/meshes/link7_brasimp.stl" scale="0.01 0.01 0.01"/>   
    </geometry>
  </collision>
</link>

<joint name="joint_7_8_l2" type="continuous">
  <origin xyz="0.0708 0.0 0.05" rpy="0.0 0.0 0.0"/>
  <parent link="link7_brasimp_l2"/>
  <child link="link8_band_l2"/>
  <axis xyz="0.0 0.0 1.0"/>
</joint>

<link name="link8_band_l2">
  <inertial>
    <origin xyz="0.0 0.0 0.0" rpy="0.0 0.0 0.0"/>
    <mass value="0.0"/>
    <inertia ixx="0.0" ixy="0.0" ixz="0.0" iyy="0.0" iyz="0.0" izz="0.0"/>
  </inertial>
  <visual name="">
    <origin xyz="0.0 0.0 0.0" rpy="0.0 0.0 0.0"/>
      <geometry>
      <mesh filename="package://plat4m_description/meshes/link8_band.stl" scale="0.01 0.01 0.01"/>   
    </geometry>
    <material name="">
      <color rgba="1.0 0.0 0.0 1.0"/>
      <texture filename=""/>
    </material>
  </visual>
  <collision>
    <origin xyz="0.0 0.0 0.0" rpy="0.0 0.0 0.0"/>
    <geometry>
      <mesh filename="package://plat4m_description/meshes/link8_band.stl" scale="0.01 0.01 0.01"/>   
    </geometry>
  </collision>
</link>
<!-- _______________________________________________________________________________________________ -->
<link name="link4_bras_l1">
  <inertial>
    <origin xyz="0.0 0.0 0.0" rpy="0.0 0.0 0.0"/>
    <mass value="0.0"/>
    <inertia ixx="0.0" ixy="0.0" ixz="0.0" iyy="0.0" iyz="0.0" izz="0.0"/>
  </inertial>
  <visual name="">
    <origin xyz="0.0 0.0 0.0" rpy="0.0 0.0 0.0"/>
      <geometry>
      <mesh filename="package://plat4m_description/meshes/link4_bras.stl" scale="0.01 0.01 0.01"/>   
    </geometry>
    <material name="">
      <color rgba="1.0 0.0 0.0 1.0"/>
      <texture filename=""/>
    </material>
  </visual>
  <collision>
    <origin xyz="0.0 0.0 0.0" rpy="0.0 0.0 0.0"/>
    <geometry>
      <mesh filename="package://plat4m_description/meshes/link4_bras.stl" scale="0.01 0.01 0.01"/>   
    </geometry>
  </collision>
</link>

<joint name="joint_0_5_l1" type="fixed">
  <origin xyz="0.65 0.9 0.01935" rpy="0.0 0.0 0.0"/>
  <parent link="link0_p4m"/>
  <child link="link5_atpiv_l1"/>
</joint>

<joint name="joint_4_5_l1" type="revolute">
  <origin xyz="0.0 0 0.0161" rpy="0.0 0.0 0.0"/>
  <parent link="link5_atpiv_l1"/>
  <child link="link4_bras_l1"/>
  <axis xyz="0.0 -1.0 0.0"/>
  <limit lower="0.000" upper="1" effort="100.0" velocity="20.0"/>
</joint>

<link name="link5_atpiv_l1">
  <inertial>
    <origin xyz="0.0 0.0 0.0" rpy="0.0 0.0 0.0"/>
    <mass value="0.0"/>
    <inertia ixx="0.0" ixy="0.0" ixz="0.0" iyy="0.0" iyz="0.0" izz="0.0"/>
  </inertial>
  <visual name="">
    <origin xyz="0.0 0.0 0.0" rpy="0.0 0.0 0.0"/>
      <geometry>
      <mesh filename="package://plat4m_description/meshes/link5_atpiv.stl" scale="0.01 0.01 0.01"/>   
    </geometry>
    <material name="">
      <color rgba="1.0 0.0 0.0 1.0"/>
      <texture filename=""/>
    </material>
  </visual>
  <collision>
    <origin xyz="0.0 0.0 0.0" rpy="0.0 0.0 0.0"/>
    <geometry>
      <mesh filename="package://plat4m_description/meshes/link5_atpiv.stl" scale="0.01 0.01 0.01"/>   
    </geometry>
  </collision>
</link>

<joint name="joint_5_6_l1" type="continuous">
  <origin xyz="0.120 0 -0.033" rpy="0.0 -0.27 0.0"/>
  <parent link="link4_bras_l1"/>
  <child link="link6_roubi_l1"/>
  <axis xyz="1.0 0.0 0.0"/>
</joint>

<link name="link6_roubi_l1">
  <inertial>
    <origin xyz="0.0 0.0 0.0" rpy="0.0 0.0 0.0"/>
    <mass value="0.0"/>
    <inertia ixx="0.0" ixy="0.0" ixz="0.0" iyy="0.0" iyz="0.0" izz="0.0"/>
  </inertial>
  <visual name="">
    <origin xyz="0.0 0.0 0.0" rpy="0.0 0.0 0.0"/>
      <geometry>
      <mesh filename="package://plat4m_description/meshes/link6_roubi.stl" scale="0.01 0.01 0.01"/>   
    </geometry>
    <material name="">
      <color rgba="1.0 0.0 0.0 1.0"/>
      <texture filename=""/>
    </material>
  </visual>
  <collision>
    <origin xyz="0.0 0.0 0.0" rpy="0.0 0.0 0.0"/>
    <geometry>
      <mesh filename="package://plat4m_description/meshes/link6_roubi.stl" scale="0.01 0.01 0.01"/>   
    </geometry>
  </collision>
</link>

<joint name="joint_0_7_l1" type="prismatic">
  <origin xyz="0.7 0.98 0.01935" rpy="0.0 0.0 0.0"/>
  <parent link="link0_p4m"/>
  <child link="link7_brasimp_l1"/>
  <axis xyz="-1.0 0.0 0.0"/>
  <limit lower="0.0" upper="0.1" effort="20.0" velocity="20.0"/>
</joint>

<link name="link7_brasimp_l1">
  <inertial>
    <origin xyz="0.0 0.0 0.0" rpy="0.0 0.0 0.0"/>
    <mass value="0.0"/>
    <inertia ixx="0.0" ixy="0.0" ixz="0.0" iyy="0.0" iyz="0.0" izz="0.0"/>
  </inertial>
  <visual name="">
    <origin xyz="0.0 0.0 0.0" rpy="0.0 0.0 0.0"/>
      <geometry>
      <mesh filename="package://plat4m_description/meshes/link7_brasimp.stl" scale="0.01 0.01 0.01"/>   
    </geometry>
    <material name="">
      <color rgba="1.0 0.0 0.0 1.0"/>
      <texture filename=""/>
    </material>
  </visual>
  <collision>
    <origin xyz="0.0 0.0 0.0" rpy="0.0 0.0 0.0"/>
    <geometry>
      <mesh filename="package://plat4m_description/meshes/link7_brasimp.stl" scale="0.01 0.01 0.01"/>   
    </geometry>
  </collision>
</link>

<joint name="joint_7_8_l1" type="continuous">
  <origin xyz="0.0708 0 0.05" rpy="0.0 0.0 0.0"/>
  <parent link="link7_brasimp_l1"/>
  <child link="link8_band_l1"/>
  <axis xyz="0.0 0.0 1.0"/>
</joint>
<link name="link8_band_l1">
  <inertial>
    <origin xyz="0.0 0.0 0.0" rpy="0.0 0.0 0.0"/>
    <mass value="0.0"/>
    <inertia ixx="0.0" ixy="0.0" ixz="0.0" iyy="0.0" iyz="0.0" izz="0.0"/>
  </inertial>
  <visual name="">
    <origin xyz="0.0 0.0 0.0" rpy="0.0 0.0 0.0"/>
      <geometry>
      <mesh filename="package://plat4m_description/meshes/link8_band.stl" scale="0.01 0.01 0.01"/>   
    </geometry>
    <material name="">
      <color rgba="1.0 0.0 0.0 1.0"/>
      <texture filename=""/>
    </material>
  </visual>
  <collision>
    <origin xyz="0.0 0.0 0.0" rpy="0.0 0.0 0.0"/>
    <geometry>
      <mesh filename="package://plat4m_description/meshes/link8_band.stl" scale="0.01 0.01 0.01"/>   
    </geometry>
  </collision>
</link>


<!-- _______________________________________________________________________________________________ -->
<link name="link4_bras_l3">
  <inertial>
    <origin xyz="0.0 0.0 0.0" rpy="0.0 0.0 0.0"/>
    <mass value="0.0"/>
    <inertia ixx="0.0" ixy="0.0" ixz="0.0" iyy="0.0" iyz="0.0" izz="0.0"/>
  </inertial>
  <visual name="">
    <origin xyz="0.0 0.0 0.0" rpy="0.0 0.0 0.0"/>
      <geometry>
      <mesh filename="package://plat4m_description/meshes/link4_bras.stl" scale="0.01 0.01 0.01"/>   
    </geometry>
    <material name="">
      <color rgba="1.0 0.0 0.0 1.0"/>
      <texture filename=""/>
    </material>
  </visual>
  <collision>
    <origin xyz="0.0 0.0 0.0" rpy="0.0 0.0 0.0"/>
    <geometry>
      <mesh filename="package://plat4m_description/meshes/link4_bras.stl" scale="0.01 0.01 0.01"/>   
    </geometry>
  </collision>
</link>

<joint name="joint_0_5_l3" type="fixed">
  <origin xyz="0.65 -0.9 0.01935" rpy="0.0 0.0 0.0"/>
  <parent link="link0_p4m"/>
  <child link="link5_atpiv_l3"/>
</joint>

<joint name="joint_4_5_l3" type="revolute">
  <origin xyz="0.0 0 0.0161" rpy="0.0 0.0 0.0"/>
  <parent link="link5_atpiv_l3"/>
  <child link="link4_bras_l3"/>
  <axis xyz="0.0 -1.0 0.0"/>
  <limit lower="0.000" upper="1" effort="100.0" velocity="20.0"/>
</joint>

<link name="link5_atpiv_l3">
  <inertial>
    <origin xyz="0.0 0.0 0.0" rpy="0.0 0.0 0.0"/>
    <mass value="0.0"/>
    <inertia ixx="0.0" ixy="0.0" ixz="0.0" iyy="0.0" iyz="0.0" izz="0.0"/>
  </inertial>
  <visual name="">
    <origin xyz="0.0 0.0 0.0" rpy="0.0 0.0 0.0"/>
      <geometry>
      <mesh filename="package://plat4m_description/meshes/link5_atpiv.stl" scale="0.01 0.01 0.01"/>   
    </geometry>
    <material name="">
      <color rgba="1.0 0.0 0.0 1.0"/>
      <texture filename=""/>
    </material>
  </visual>
  <collision>
    <origin xyz="0.0 0.0 0.0" rpy="0.0 0.0 0.0"/>
    <geometry>
      <mesh filename="package://plat4m_description/meshes/link5_atpiv.stl" scale="0.01 0.01 0.01"/>   
    </geometry>
  </collision>
</link>

<joint name="joint_5_6_l3" type="continuous">
  <origin xyz="0.120 0 -0.033" rpy="0.0 -0.27 0.0"/>
  <parent link="link4_bras_l3"/>
  <child link="link6_roubi_l3"/>
  <axis xyz="1.0 0.0 0.0"/>
</joint>

<link name="link6_roubi_l3">
  <inertial>
    <origin xyz="0.0 0.0 0.0" rpy="0.0 0.0 0.0"/>
    <mass value="0.0"/>
    <inertia ixx="0.0" ixy="0.0" ixz="0.0" iyy="0.0" iyz="0.0" izz="0.0"/>
  </inertial>
  <visual name="">
    <origin xyz="0.0 0.0 0.0" rpy="0.0 0.0 0.0"/>
      <geometry>
      <mesh filename="package://plat4m_description/meshes/link6_roubi.stl" scale="0.01 0.01 0.01"/>   
    </geometry>
    <material name="">
      <color rgba="1.0 0.0 0.0 1.0"/>
      <texture filename=""/>
    </material>
  </visual>
  <collision>
    <origin xyz="0.0 0.0 0.0" rpy="0.0 0.0 0.0"/>
    <geometry>
      <mesh filename="package://plat4m_description/meshes/link6_roubi.stl" scale="0.01 0.01 0.01"/>   
    </geometry>
  </collision>
</link>

<joint name="joint_0_7_l3" type="prismatic">
  <origin xyz="0.7 -0.98 0.01935" rpy="0.0 0.0 0.0"/>
  <parent link="link0_p4m"/>
  <child link="link7_brasimp_l3"/>
  <axis xyz="-1.0 0.0 0.0"/>
  <limit lower="0.0" upper="0.1" effort="20.0" velocity="20.0"/>
</joint>

<link name="link7_brasimp_l3">
  <inertial>
    <origin xyz="0.0 0.0 0.0" rpy="0.0 0.0 0.0"/>
    <mass value="0.0"/>
    <inertia ixx="0.0" ixy="0.0" ixz="0.0" iyy="0.0" iyz="0.0" izz="0.0"/>
  </inertial>
  <visual name="">
    <origin xyz="0.0 0.0 0.0" rpy="0.0 0.0 0.0"/>
      <geometry>
      <mesh filename="package://plat4m_description/meshes/link7_brasimp.stl" scale="0.01 0.01 0.01"/>   
    </geometry>
    <material name="">
      <color rgba="1.0 0.0 0.0 1.0"/>
      <texture filename=""/>
    </material>
  </visual>
  <collision>
    <origin xyz="0.0 0.0 0.0" rpy="0.0 0.0 0.0"/>
    <geometry>
      <mesh filename="package://plat4m_description/meshes/link7_brasimp.stl" scale="0.01 0.01 0.01"/>   
    </geometry>
  </collision>
</link>

<joint name="joint_7_8_l3" type="continuous">
  <origin xyz="0.0708 0 0.05" rpy="0.0 0.0 0.0"/>
  <parent link="link7_brasimp_l3"/>
  <child link="link8_band_l3"/>
  <axis xyz="0.0 0.0 1.0"/>
</joint>
<link name="link8_band_l3">
  <inertial>
    <origin xyz="0.0 0.0 0.0" rpy="0.0 0.0 0.0"/>
    <mass value="0.0"/>
    <inertia ixx="0.0" ixy="0.0" ixz="0.0" iyy="0.0" iyz="0.0" izz="0.0"/>
  </inertial>
  <visual name="">
    <origin xyz="0.0 0.0 0.0" rpy="0.0 0.0 0.0"/>
      <geometry>
      <mesh filename="package://plat4m_description/meshes/link8_band.stl" scale="0.01 0.01 0.01"/>   
    </geometry>
    <material name="">
      <color rgba="1.0 0.0 0.0 1.0"/>
      <texture filename=""/>
    </material>
  </visual>
  <collision>
    <origin xyz="0.0 0.0 0.0" rpy="0.0 0.0 0.0"/>
    <geometry>
      <mesh filename="package://plat4m_description/meshes/link8_band.stl" scale="0.01 0.01 0.01"/>   
    </geometry>
  </collision>
</link>

<!---->
<!---->


<joint name="joint_0_1_r2" type="fixed">
  <origin xyz="-0.50 0.0 0.01935" rpy="0.0 0.0 3.1416"/>
  <parent link="link0_p4m"/>
  <child link="link1_atache_r2"/>
</joint>


<link name="link1_atache_r2">
  <inertial>
    <origin xyz="0.0 0.0 0.0" rpy="0.0 0.0 0.0"/>
    <mass value="0.0"/>
    <inertia ixx="0.0" ixy="0.0" ixz="0.0" iyy="0.0" iyz="0.0" izz="0.0"/>
  </inertial>
  <visual name="">
    <origin xyz="0.0 0.0 0.0" rpy="0.0 0.0 0.0"/>
    <geometry>
      <mesh filename="package://plat4m_description/meshes/link1_atache.stl" scale="0.01 0.01 0.01"/>
    </geometry>
    <material name="">
      <color rgba="1.0 0.0 0.0 1.0"/>
      <texture filename=""/>
    </material>
  </visual>
  <collision>
    <origin xyz="0.0 0.0 0.0" rpy="0.0 0.0 0.0"/>
    <geometry>
      <mesh filename="package://plat4m_description/meshes/link1_atache.stl" scale="0.01 0.01 0.01"/>
    </geometry>
  </collision>
</link>

<joint name="joint_1_2_r2" type="continuous">
  <origin xyz="0.000 0.000 0.021" rpy="0.0 0.0 0.0"/>
  <parent link="link1_atache_r2"/>
  <child link="link2_act_r2"/>
  <axis xyz="0.0 1.0 0.0"/>
</joint>

<link name="link2_act_r2">
  <inertial>
    <origin xyz="0.0 0.0 0.0" rpy="0.0 0.0 0.0"/>
    <mass value="0.0"/>
    <inertia ixx="0.0" ixy="0.0" ixz="0.0" iyy="0.0" iyz="0.0" izz="0.0"/>
  </inertial>
  <visual name="">
    <origin xyz="0.0 0.0 0.0" rpy="0.0 0.0 0.0"/>
    <geometry>
      <mesh filename="package://plat4m_description/meshes/link2_act.stl" scale="0.01 0.01 0.01"/>   
       </geometry>
    <material name="">
      <color rgba="1.0 0.0 0.0 1.0"/>
      <texture filename=""/>
    </material>
  </visual>
  <collision>
    <origin xyz="0.0 0.0 0.0" rpy="0.0 0.0 0.0"/>
    <geometry>
      <mesh filename="package://plat4m_description/meshes/link2_act.stl" scale="0.01 0.01 0.01"/>   
    </geometry>
  </collision>
</link>

<joint name="joint_2_3_r2" type="prismatic">
  <origin xyz="0.03 0.0 0.0" rpy="0.0 0.0 0.0"/>
  <parent link="link2_act_r2"/>
  <child link="link3_tige_r2"/>
  <axis xyz="1.0 0.0 0.0"/>
  <limit lower="0.000" upper="0.070" effort="100.0" velocity="20.0"/>
</joint>

<link name="link3_tige_r2">
  <inertial>
    <origin xyz="0.0 0.0 0.0" rpy="0.0 0.0 0.0"/>
    <mass value="0.0"/>
    <inertia ixx="0.0" ixy="0.0" ixz="0.0" iyy="0.0" iyz="0.0" izz="0.0"/>
  </inertial>
  <visual name="">
    <origin xyz="0.0 0.0 0.0" rpy="0.0 0.0 0.0"/>
      <geometry>
      <mesh filename="package://plat4m_description/meshes/link3_tige.stl" scale="0.01 0.01 0.01"/>   
    </geometry>
    <material name="">
      <color rgba="1.0 0.0 0.0 1.0"/>
      <texture filename=""/>
    </material>
  </visual>
  <collision>
    <origin xyz="0.0 0.0 0.0" rpy="0.0 0.0 0.0"/>
    <geometry>
      <mesh filename="package://plat4m_description/meshes/link3_tige.stl" scale="0.01 0.01 0.01"/>   
    </geometry>
  </collision>
</link>


<link name="link4_bras_r2">
  <inertial>
    <origin xyz="0.0 0.0 0.0" rpy="0.0 0.0 0.0"/>
    <mass value="0.0"/>
    <inertia ixx="0.0" ixy="0.0" ixz="0.0" iyy="0.0" iyz="0.0" izz="0.0"/>
  </inertial>
  <visual name="">
    <origin xyz="0.0 0.0 0.0" rpy="0.0 0.0 0.0"/>
      <geometry>
      <mesh filename="package://plat4m_description/meshes/link4_bras.stl" scale="0.01 0.01 0.01"/>   
    </geometry>
    <material name="">
      <color rgba="1.0 0.0 0.0 1.0"/>
      <texture filename=""/>
    </material>
  </visual>
  <collision>
    <origin xyz="0.0 0.0 0.0" rpy="0.0 0.0 0.0"/>
    <geometry>
      <mesh filename="package://plat4m_description/meshes/link4_bras.stl" scale="0.01 0.01 0.01"/>   
    </geometry>
  </collision>
</link>

<joint name="joint_0_5_r2" type="fixed">
  <origin xyz="-0.65 0.0 0.01935" rpy="0.0 0.0 3.1416"/>
  <parent link="link0_p4m"/>
  <child link="link5_atpiv_r2"/>
</joint>

<joint name="joint_4_5_r2" type="revolute">
  <origin xyz="0.0 0.0 0.0161" rpy="0.0 0.0 0.0"/>
  <parent link="link5_atpiv_r2"/>
  <child link="link4_bras_r2"/>
  <axis xyz="0.0 -1.0 0.0"/>
  <limit lower="0.000" upper="1" effort="100.0" velocity="20.0"/>
</joint>

<link name="link5_atpiv_r2">
  <inertial>
    <origin xyz="0.0 0.0 0.0" rpy="0.0 0.0 0.0"/>
    <mass value="0.0"/>
    <inertia ixx="0.0" ixy="0.0" ixz="0.0" iyy="0.0" iyz="0.0" izz="0.0"/>
  </inertial>
  <visual name="">
    <origin xyz="0.0 0.0 0.0" rpy="0.0 0.0 0.0"/>
      <geometry>
      <mesh filename="package://plat4m_description/meshes/link5_atpiv.stl" scale="0.01 0.01 0.01"/>   
    </geometry>
    <material name="">
      <color rgba="1.0 0.0 0.0 1.0"/>
      <texture filename=""/>
    </material>
  </visual>
  <collision>
    <origin xyz="0.0 0.0 0.0" rpy="0.0 0.0 0.0"/>
    <geometry>
      <mesh filename="package://plat4m_description/meshes/link5_atpiv.stl" scale="0.01 0.01 0.01"/>   
    </geometry>
  </collision>
</link>

<joint name="joint_5_6_r2" type="continuous">
  <origin xyz="0.120 0.000 -0.033" rpy="0.0 -0.27 0.0"/>
  <parent link="link4_bras_r2"/>
  <child link="link6_roubi_r2"/>
  <axis xyz="-1.0 0.0 0.0"/>
</joint>

<link name="link6_roubi_r2">
  <inertial>
    <origin xyz="0.0 0.0 0.0" rpy="0.0 0.0 0.0"/>
    <mass value="0.0"/>
    <inertia ixx="0.0" ixy="0.0" ixz="0.0" iyy="0.0" iyz="0.0" izz="0.0"/>
  </inertial>
  <visual name="">
    <origin xyz="0.0 0.0 0.0" rpy="0.0 0.0 0.0"/>
      <geometry>
      <mesh filename="package://plat4m_description/meshes/link6_roubi.stl" scale="0.01 0.01 0.01"/>   
    </geometry>
    <material name="">
      <color rgba="1.0 0.0 0.0 1.0"/>
      <texture filename=""/>
    </material>
  </visual>
  <collision>
    <origin xyz="0.0 0.0 0.0" rpy="0.0 0.0 0.0"/>
    <geometry>
      <mesh filename="package://plat4m_description/meshes/link6_roubi.stl" scale="0.01 0.01 0.01"/>   
    </geometry>
  </collision>
</link>

<joint name="joint_0_7_r2" type="prismatic">
  <origin xyz="-0.7 0.1 0.01935" rpy="0.0 0.0 3.1416"/>
  <parent link="link0_p4m"/>
  <child link="link7_brasimp_r2"/>
  <axis xyz="-1.0 0.0 0.0"/>
  <limit lower="0.0" upper="0.1" effort="20.0" velocity="20.0"/>
</joint>

<link name="link7_brasimp_r2">
  <inertial>
    <origin xyz="0.0 0.0 0.0" rpy="0.0 0.0 0.0"/>
    <mass value="0.0"/>
    <inertia ixx="0.0" ixy="0.0" ixz="0.0" iyy="0.0" iyz="0.0" izz="0.0"/>
  </inertial>
  <visual name="">
    <origin xyz="0.0 0.0 0.0" rpy="0.0 0.0 0.0"/>
      <geometry>
      <mesh filename="package://plat4m_description/meshes/link7_brasimp.stl" scale="0.01 0.01 0.01"/>   
    </geometry>
    <material name="">
      <color rgba="1.0 0.0 0.0 1.0"/>
      <texture filename=""/>
    </material>
  </visual>
  <collision>
    <origin xyz="0.0 0.0 0.0" rpy="0.0 0.0 0.0"/>
    <geometry>
      <mesh filename="package://plat4m_description/meshes/link7_brasimp.stl" scale="0.01 0.01 0.01"/>   
    </geometry>
  </collision>
</link>

<joint name="joint_7_8_r2" type="continuous">
  <origin xyz="0.0708 0.0 0.05" rpy="0.0 0.0 0.0"/>
  <parent link="link7_brasimp_r2"/>
  <child link="link8_band_r2"/>
  <axis xyz="0.0 0.0 1.0"/>
</joint>

<link name="link8_band_r2">
  <inertial>
    <origin xyz="0.0 0.0 0.0" rpy="0.0 0.0 0.0"/>
    <mass value="0.0"/>
    <inertia ixx="0.0" ixy="0.0" ixz="0.0" iyy="0.0" iyz="0.0" izz="0.0"/>
  </inertial>
  <visual name="">
    <origin xyz="0.0 0.0 0.0" rpy="0.0 0.0 0.0"/>
      <geometry>
      <mesh filename="package://plat4m_description/meshes/link8_band.stl" scale="0.01 0.01 0.01"/>   
    </geometry>
    <material name="">
      <color rgba="1.0 0.0 0.0 1.0"/>
      <texture filename=""/>
    </material>
  </visual>
  <collision>
    <origin xyz="0.0 0.0 0.0" rpy="0.0 0.0 0.0"/>
    <geometry>
      <mesh filename="package://plat4m_description/meshes/link8_band.stl" scale="0.01 0.01 0.01"/>   
    </geometry>
  </collision>
</link>
<!-- _______________________________________________________________________________________________ -->

<link name="link4_bras_r1">
  <inertial>
    <origin xyz="0.0 0.0 0.0" rpy="0.0 0.0 0.0"/>
    <mass value="0.0"/>
    <inertia ixx="0.0" ixy="0.0" ixz="0.0" iyy="0.0" iyz="0.0" izz="0.0"/>
  </inertial>
  <visual name="">
    <origin xyz="0.0 0.0 0.0" rpy="0.0 0.0 0.0"/>
      <geometry>
      <mesh filename="package://plat4m_description/meshes/link4_bras.stl" scale="0.01 0.01 0.01"/>   
    </geometry>
    <material name="">
      <color rgba="1.0 0.0 0.0 1.0"/>
      <texture filename=""/>
    </material>
  </visual>
  <collision>
    <origin xyz="0.0 0.0 0.0" rpy="0.0 0.0 0.0"/>
    <geometry>
      <mesh filename="package://plat4m_description/meshes/link4_bras.stl" scale="0.01 0.01 0.01"/>   
    </geometry>
  </collision>
</link>

<joint name="joint_0_5_r1" type="fixed">
  <origin xyz="-0.65 0.9 0.01935" rpy="0.0 0.0 3.1416"/>
  <parent link="link0_p4m"/>
  <child link="link5_atpiv_r1"/>
</joint>

<joint name="joint_4_5_r1" type="revolute">
  <origin xyz="0.0 0 0.0161" rpy="0.0 0.0 0.0"/>
  <parent link="link5_atpiv_r1"/>
  <child link="link4_bras_r1"/>
  <axis xyz="0.0 -1.0 0.0"/>
  <limit lower="0.000" upper="1" effort="100.0" velocity="20.0"/>
</joint>

<link name="link5_atpiv_r1">
  <inertial>
    <origin xyz="0.0 0.0 0.0" rpy="0.0 0.0 0.0"/>
    <mass value="0.0"/>
    <inertia ixx="0.0" ixy="0.0" ixz="0.0" iyy="0.0" iyz="0.0" izz="0.0"/>
  </inertial>
  <visual name="">
    <origin xyz="0.0 0.0 0.0" rpy="0.0 0.0 0.0"/>
      <geometry>
      <mesh filename="package://plat4m_description/meshes/link5_atpiv.stl" scale="0.01 0.01 0.01"/>   
    </geometry>
    <material name="">
      <color rgba="1.0 0.0 0.0 1.0"/>
      <texture filename=""/>
    </material>
  </visual>
  <collision>
    <origin xyz="0.0 0.0 0.0" rpy="0.0 0.0 0.0"/>
    <geometry>
      <mesh filename="package://plat4m_description/meshes/link5_atpiv.stl" scale="0.01 0.01 0.01"/>   
    </geometry>
  </collision>
</link>

<joint name="joint_5_6_r1" type="continuous">
  <origin xyz="0.120 0 -0.033" rpy="0.0 -0.27 0.0"/>
  <parent link="link4_bras_r1"/>
  <child link="link6_roubi_r1"/>
  <axis xyz="1.0 0.0 0.0"/>
</joint>

<link name="link6_roubi_r1">
  <inertial>
    <origin xyz="0.0 0.0 0.0" rpy="0.0 0.0 0.0"/>
    <mass value="0.0"/>
    <inertia ixx="0.0" ixy="0.0" ixz="0.0" iyy="0.0" iyz="0.0" izz="0.0"/>
  </inertial>
  <visual name="">
    <origin xyz="0.0 0.0 0.0" rpy="0.0 0.0 0.0"/>
      <geometry>
      <mesh filename="package://plat4m_description/meshes/link6_roubi.stl" scale="0.01 0.01 0.01"/>   
    </geometry>
    <material name="">
      <color rgba="1.0 0.0 0.0 1.0"/>
      <texture filename=""/>
    </material>
  </visual>
  <collision>
    <origin xyz="0.0 0.0 0.0" rpy="0.0 0.0 0.0"/>
    <geometry>
      <mesh filename="package://plat4m_description/meshes/link6_roubi.stl" scale="0.01 0.01 0.01"/>   
    </geometry>
  </collision>
</link>

<joint name="joint_0_7_r1" type="prismatic">
  <origin xyz="-0.7 0.98 0.01935" rpy="0.0 0.0 3.1416"/>
  <parent link="link0_p4m"/>
  <child link="link7_brasimp_r1"/>
  <axis xyz="-1.0 0.0 0.0"/>
  <limit lower="0.0" upper="0.1" effort="20.0" velocity="20.0"/>
</joint>

<link name="link7_brasimp_r1">
  <inertial>
    <origin xyz="0.0 0.0 0.0" rpy="0.0 0.0 0.0"/>
    <mass value="0.0"/>
    <inertia ixx="0.0" ixy="0.0" ixz="0.0" iyy="0.0" iyz="0.0" izz="0.0"/>
  </inertial>
  <visual name="">
    <origin xyz="0.0 0.0 0.0" rpy="0.0 0.0 0.0"/>
      <geometry>
      <mesh filename="package://plat4m_description/meshes/link7_brasimp.stl" scale="0.01 0.01 0.01"/>   
    </geometry>
    <material name="">
      <color rgba="1.0 0.0 0.0 1.0"/>
      <texture filename=""/>
    </material>
  </visual>
  <collision>
    <origin xyz="0.0 0.0 0.0" rpy="0.0 0.0 0.0"/>
    <geometry>
      <mesh filename="package://plat4m_description/meshes/link7_brasimp.stl" scale="0.01 0.01 0.01"/>   
    </geometry>
  </collision>
</link>

<joint name="joint_7_8_r1" type="continuous">
  <origin xyz="0.0708 0 0.05" rpy="0.0 0.0 0.0"/>
  <parent link="link7_brasimp_r1"/>
  <child link="link8_band_r1"/>
  <axis xyz="0.0 0.0 1.0"/>
</joint>
<link name="link8_band_r1">
  <inertial>
    <origin xyz="0.0 0.0 0.0" rpy="0.0 0.0 0.0"/>
    <mass value="0.0"/>
    <inertia ixx="0.0" ixy="0.0" ixz="0.0" iyy="0.0" iyz="0.0" izz="0.0"/>
  </inertial>
  <visual name="">
    <origin xyz="0.0 0.0 0.0" rpy="0.0 0.0 0.0"/>
      <geometry>
      <mesh filename="package://plat4m_description/meshes/link8_band.stl" scale="0.01 0.01 0.01"/>   
    </geometry>
    <material name="">
      <color rgba="1.0 0.0 0.0 1.0"/>
      <texture filename=""/>
    </material>
  </visual>
  <collision>
    <origin xyz="0.0 0.0 0.0" rpy="0.0 0.0 0.0"/>
    <geometry>
      <mesh filename="package://plat4m_description/meshes/link8_band.stl" scale="0.01 0.01 0.01"/>   
    </geometry>
  </collision>
</link>


<!-- _______________________________________________________________________________________________ -->
<link name="link4_bras_r3">
  <inertial>
    <origin xyz="0.0 0.0 0.0" rpy="0.0 0.0 0.0"/>
    <mass value="0.0"/>
    <inertia ixx="0.0" ixy="0.0" ixz="0.0" iyy="0.0" iyz="0.0" izz="0.0"/>
  </inertial>
  <visual name="">
    <origin xyz="0.0 0.0 0.0" rpy="0.0 0.0 0.0"/>
      <geometry>
      <mesh filename="package://plat4m_description/meshes/link4_bras.stl" scale="0.01 0.01 0.01"/>   
    </geometry>
    <material name="">
      <color rgba="1.0 0.0 0.0 1.0"/>
      <texture filename=""/>
    </material>
  </visual>
  <collision>
    <origin xyz="0.0 0.0 0.0" rpy="0.0 0.0 0.0"/>
    <geometry>
      <mesh filename="package://plat4m_description/meshes/link4_bras.stl" scale="0.01 0.01 0.01"/>   
    </geometry>
  </collision>
</link>

<joint name="joint_0_5_r3" type="fixed">
  <origin xyz="-0.65 -0.9 0.01935" rpy="0.0 0.0 3.1416"/>
  <parent link="link0_p4m"/>
  <child link="link5_atpiv_r3"/>
</joint>

<joint name="joint_4_5_r3" type="revolute">
  <origin xyz="0.0 0 0.0161" rpy="0.0 0.0 0.0"/>
  <parent link="link5_atpiv_r3"/>
  <child link="link4_bras_r3"/>
  <axis xyz="0.0 -1.0 0.0"/>
  <limit lower="0.000" upper="1" effort="100.0" velocity="20.0"/>
</joint>

<link name="link5_atpiv_r3">
  <inertial>
    <origin xyz="0.0 0.0 0.0" rpy="0.0 0.0 0.0"/>
    <mass value="0.0"/>
    <inertia ixx="0.0" ixy="0.0" ixz="0.0" iyy="0.0" iyz="0.0" izz="0.0"/>
  </inertial>
  <visual name="">
    <origin xyz="0.0 0.0 0.0" rpy="0.0 0.0 0.0"/>
      <geometry>
      <mesh filename="package://plat4m_description/meshes/link5_atpiv.stl" scale="0.01 0.01 0.01"/>   
    </geometry>
    <material name="">
      <color rgba="1.0 0.0 0.0 1.0"/>
      <texture filename=""/>
    </material>
  </visual>
  <collision>
    <origin xyz="0.0 0.0 0.0" rpy="0.0 0.0 0.0"/>
    <geometry>
      <mesh filename="package://plat4m_description/meshes/link5_atpiv.stl" scale="0.01 0.01 0.01"/>   
    </geometry>
  </collision>
</link>

<joint name="joint_5_6_r3" type="continuous">
  <origin xyz="0.120 0 -0.033" rpy="0.0 -0.27 0.0"/>
  <parent link="link4_bras_r3"/>
  <child link="link6_roubi_r3"/>
  <axis xyz="1.0 0.0 0.0"/>
</joint>

<link name="link6_roubi_r3">
  <inertial>
    <origin xyz="0.0 0.0 0.0" rpy="0.0 0.0 0.0"/>
    <mass value="0.0"/>
    <inertia ixx="0.0" ixy="0.0" ixz="0.0" iyy="0.0" iyz="0.0" izz="0.0"/>
  </inertial>
  <visual name="">
    <origin xyz="0.0 0.0 0.0" rpy="0.0 0.0 0.0"/>
      <geometry>
      <mesh filename="package://plat4m_description/meshes/link6_roubi.stl" scale="0.01 0.01 0.01"/>   
    </geometry>
    <material name="">
      <color rgba="1.0 0.0 0.0 1.0"/>
      <texture filename=""/>
    </material>
  </visual>
  <collision>
    <origin xyz="0.0 0.0 0.0" rpy="0.0 0.0 0.0"/>
    <geometry>
      <mesh filename="package://plat4m_description/meshes/link6_roubi.stl" scale="0.01 0.01 0.01"/>   
    </geometry>
  </collision>
</link>

<joint name="joint_0_7_r3" type="prismatic">
  <origin xyz="-0.7 -0.98 0.01935" rpy="0.0 0.0 3.1416"/>
  <parent link="link0_p4m"/>
  <child link="link7_brasimp_r3"/>
  <axis xyz="-1.0 0.0 0.0"/>
  <limit lower="0.0" upper="0.1" effort="20.0" velocity="20.0"/>
</joint>

<link name="link7_brasimp_r3">
  <inertial>
    <origin xyz="0.0 0.0 0.0" rpy="0.0 0.0 0.0"/>
    <mass value="0.0"/>
    <inertia ixx="0.0" ixy="0.0" ixz="0.0" iyy="0.0" iyz="0.0" izz="0.0"/>
  </inertial>
  <visual name="">
    <origin xyz="0.0 0.0 0.0" rpy="0.0 0.0 0.0"/>
      <geometry>
      <mesh filename="package://plat4m_description/meshes/link7_brasimp.stl" scale="0.01 0.01 0.01"/>   
    </geometry>
    <material name="">
      <color rgba="1.0 0.0 0.0 1.0"/>
      <texture filename=""/>
    </material>
  </visual>
  <collision>
    <origin xyz="0.0 0.0 0.0" rpy="0.0 0.0 0.0"/>
    <geometry>
      <mesh filename="package://plat4m_description/meshes/link7_brasimp.stl" scale="0.01 0.01 0.01"/>   
    </geometry>
  </collision>
</link>

<joint name="joint_7_8_r3" type="continuous">
  <origin xyz="0.0708 0 0.05" rpy="0.0 0.0 0.0"/>
  <parent link="link7_brasimp_r3"/>
  <child link="link8_band_r3"/>
  <axis xyz="0.0 0.0 1.0"/>
</joint>

<link name="link8_band_r3">
  <inertial>
    <origin xyz="0.0 0.0 0.0" rpy="0.0 0.0 0.0"/>
    <mass value="0.0"/>
    <inertia ixx="0.0" ixy="0.0" ixz="0.0" iyy="0.0" iyz="0.0" izz="0.0"/>
  </inertial>
  <visual name="">
    <origin xyz="0.0 0.0 0.0" rpy="0.0 0.0 0.0"/>
      <geometry>
      <mesh filename="package://plat4m_description/meshes/link8_band.stl" scale="0.01 0.01 0.01"/>   
    </geometry>
    <material name="">
      <color rgba="1.0 0.0 0.0 1.0"/>
      <texture filename=""/>
    </material>
  </visual>
  <collision>
    <origin xyz="0.0 0.0 0.0" rpy="0.0 0.0 0.0"/>
    <geometry>
      <mesh filename="package://plat4m_description/meshes/link8_band.stl" scale="0.01 0.01 0.01"/>   
    </geometry>
  </collision>
</link>

</robot>

<!--
  <link
    name="link1">
    <inertial>
      <origin
        xyz="-2.08166817117217E-16 4.96130914129367E-16 -0.0428695174362807"
        rpy="0 0 0" />
      <mass
        value="0.0623333106741246" />
      <inertia
        ixx="3.12289966986531E-05"
        ixy="-1.51580221517921E-23"
        ixz="-2.09761083559255E-20"
        iyy="3.11752606255776E-05"
        iyz="1.01776302568525E-20"
        izz="3.52518421584705E-06" />
    </inertial>
    <visual>
      <origin
        xyz="0 0 0"
        rpy="0 0 0" />
      <geometry>
        <mesh
          filename="package://plat4m_description/meshes/link1.STL" />
      </geometry>
      <material
        name="">
        <color
          rgba="0.898039215686275 0.917647058823529 0.929411764705882 1" />
      </material>
    </visual>
    <collision>
      <origin
        xyz="0 0 0"
        rpy="0 0 0" />
      <geometry>
        <mesh
          filename="package://plat4m_description/meshes/link1.STL" />
      </geometry>
    </collision>
  </link>
  
  <link
    name="link2">
    <inertial>
      <origin
        xyz="-9.0205620750794E-17 -3.12250225675825E-17 0.0378111909485077"
        rpy="0 0 0" />
      <mass
        value="0.0057255526111674" />
      <inertia
        ixx="2.69673527985985E-06"
        ixy="5.29395592033938E-23"
        ixz="1.9368951030812E-22"
        iyy="2.69673527985985E-06"
        iyz="1.7443171167212E-22"
        izz="2.57649867502533E-08" />
    </inertial>
    <visual>
      <origin
        xyz="0 0 0"
        rpy="0 0 0" />
      <geometry>
        <mesh
          filename="package://plat4m_description/meshes/link2.STL" />
      </geometry>
      <material
        name="">
        <color
          rgba="0.898039215686275 0.917647058823529 0.929411764705882 1" />
      </material>
    </visual>
    <collision>
      <origin
        xyz="0 0 0"
        rpy="0 0 0" />
      <geometry>
        <mesh
          filename="package://plat4m_description/meshes/link2.STL" />
      </geometry>
    </collision>
  </link>
  <joint
    name="traslation"
    type="continuous">
    <origin
      xyz="0 0 -0.0500760774694747"
      rpy="-3.14159265358979 0 -0.206738625345615" />
    <parent
      link="link1" />
    <child
      link="link2" />
    <axis
      xyz="0 0 1" />
  </joint>
  <link
    name="link3">
    <inertial>
      <origin
        xyz="0.023665877379697 -6.7369809488016E-09 0.00400018224904277"
        rpy="0 0 0" />
      <mass
        value="0.00401003213575359" />
      <inertia
        ixx="2.14462946923184E-08"
        ixy="7.2122624208507E-13"
        ixz="-2.56783382281601E-12"
        iyy="9.47070290050122E-07"
        iyz="2.29232925071565E-12"
        izz="9.47577500734259E-07" />
    </inertial>
    <visual>
      <origin
        xyz="0 0 0"
        rpy="0 0 0" />
      <geometry>
        <mesh
          filename="package://plat4m_description/meshes/link3.STL" />
      </geometry>
      <material
        name="">
        <color
          rgba="0.898039215686275 0.917647058823529 0.929411764705882 1" />
      </material>
    </visual>
    <collision>
      <origin
        xyz="0 0 0"
        rpy="0 0 0" />
      <geometry>
        <mesh
          filename="package://plat4m_description/meshes/link3.STL" />
      </geometry>
    </collision>
  </link>
  <joint
    name="barre"
    type="fixed">
    <origin
      xyz="0 0 0.0673111909485077"
      rpy="0 0 -0.206738625345615" />
    <parent
      link="link2" />
    <child
      link="link3" />
    <axis
      xyz="0 0 0" />
  </joint>
  <link
    name="link4">
    <inertial>
      <origin
        xyz="-6.43048066429698E-08 0.0417877685339106 0.0480839512619778"
        rpy="0 0 0" />
      <mass
        value="0.0232692923128629" />
      <inertia
        ixx="4.00689738946953E-05"
        ixy="2.75450482169442E-11"
        ixz="7.2253591280745E-11"
        iyy="2.62526665886098E-05"
        iyz="-1.71192402188532E-05"
        izz="1.40076026917917E-05" />
    </inertial>
    <visual>
      <origin
        xyz="0 0 0"
        rpy="0 0 0" />
      <geometry>
        <mesh
          filename="package://plat4m_description/meshes/link4.STL" />
      </geometry>
      <material
        name="">
        <color
          rgba="0.898039215686275 0.917647058823529 0.929411764705882 1" />
      </material>
    </visual>
    <collision>
      <origin
        xyz="0 0 0"
        rpy="0 0 0" />
      <geometry>
        <mesh
          filename="package://plat4m_description/meshes/link4.STL" />
      </geometry>
    </collision>
  </link>
  <joint
    name="bras"
    type="fixed">
    <origin
      xyz="0.0400000000000002 0.0257758993609827 0.107480494560461"
      rpy="-2.66894723423017 0 0" />
    <parent
      link="link3" />
    <child
      link="link4" />
    <axis
      xyz="0 0 0" />
  </joint>
  <link
    name="link5">
    <inertial>
      <origin
        xyz="-0.00723312081339631 3.70343412966577E-19 0.000232471038117633"
        rpy="0 0 0" />
      <mass
        value="0.0072585303866948" />
      <inertia
        ixx="5.11268922533015E-07"
        ixy="-5.63749998649615E-24"
        ixz="8.02873739719955E-23"
        iyy="6.18079609429333E-07"
        iyz="7.51008293215709E-23"
        izz="3.549882352825E-07" />
    </inertial>
    <visual>
      <origin
        xyz="0 0 0"
        rpy="0 0 0" />
      <geometry>
        <mesh
          filename="package://plat4m_description/meshes/link5.STL" />
      </geometry>
      <material
        name="">
        <color
          rgba="0.898039215686275 0.917647058823529 0.929411764705882 1" />
      </material>
    </visual>
    <collision>
      <origin
        xyz="0 0 0"
        rpy="0 0 0" />
      <geometry>
        <mesh
          filename="package://plat4m_description/meshes/link5.STL" />
      </geometry>
    </collision>
  </link>
  <joint
    name="pivot_2"
    type="fixed">
    <origin
      xyz="-0.00025 0.072119017899818 0.109448446473966"
      rpy="1.5707963267949 0.51650762527068 1.5707963267949" />
    <parent
      link="link4" />
    <child
      link="link5" />
    <axis
      xyz="0 0 0" />
  </joint>
  <link
    name="link6">
    <inertial>
      <origin
        xyz="-6.03134178910993E-16 -2.63677968348475E-16 0.00349999999999991"
        rpy="0 0 0" />
      <mass
        value="0.00623449062104895" />
      <inertia
        ixx="2.3898880714021E-07"
        ixy="1.55521594664243E-24"
        ixz="-1.48256310603659E-24"
        iyy="2.3898880714021E-07"
        iyz="6.61744490042422E-24"
        izz="4.27062607541853E-07" />
    </inertial>
    <visual>
      <origin
        xyz="0 0 0"
        rpy="0 0 0" />
      <geometry>
        <mesh
          filename="package://plat4m_description/meshes/link6.STL" />
      </geometry>
      <material
        name="">
        <color
          rgba="0.898039215686275 0.917647058823529 0.929411764705882 1" />
      </material>
    </visual>
    <collision>
      <origin
        xyz="0 0 0"
        rpy="0 0 0" />
      <geometry>
        <mesh
          filename="package://plat4m_description/meshes/link6.STL" />
      </geometry>
    </collision>
  </link>
  <joint
    name="roue"
    type="fixed">
    <origin
      xyz="-0.0135987788495906 -0.122091029411335 0.000249999999999986"
      rpy="1.05428870152422 -1.5707963267949 0" />
    <parent
      link="link5" />
    <child
      link="link6" />
    <axis
      xyz="0 0 0" />
  </joint>-->